Workbook
Name FechaInicioProyecto: Configuración!$B$4
Name Feriados_BO_2026: Configuración!$A$14:$A$24
Name HorizonteDias: Configuración!$B$5

Sheet Configuración
A1: Parámetros del Proyecto
A3: Parámetros de tiempo
A4: Fecha de inicio del proyecto: | B4: 46113 | C4: ← Cambia la fecha de inicio aquí
A5: Horizonte (días hábiles): | B5: 84 | C5: ← Días hábiles a mostrar (máx. 260)
A7: Fecha estimada de fin: | B7: =WORKDAY(B4,B5-1,Feriados_BO_2026) -> 46233 | C7: ← Calculado con DIA.LAB excluyendo feriados
A8: Duración aproximada: | B8: =ROUND(B5/21.7,1)&" meses ("&B5&" días hábiles)" -> 3,9 meses (84 días hábiles)
A10: Nota: el Gantt soporta hasta 260 días hábiles. Modifica B5 para expandir/contraer el horizonte.
A12: Feriados nacionales de Bolivia — 2026
A13: Fecha | B13: Feriado | C13: Día | D13: Notas
A14: 46023 | B14: Año Nuevo | C14: =TEXT(A14,"dddd") -> jueves | D14: Feriado fijo
A15: 46044 | B15: Día del Estado Plurinacional | C15: =TEXT(A15,"dddd") -> jueves | D15: 22 Ene
A16: 46069 | B16: Carnaval (lunes) | C16: =TEXT(A16,"dddd") -> lunes | D16: 46069
A17: 46070 | B17: Carnaval (martes) | C17: =TEXT(A17,"dddd") -> martes | D17: 46070
A18: 46115 | B18: Viernes Santo | C18: =TEXT(A18,"dddd") -> viernes | D18: 3 Abr
A19: 46143 | B19: Día del Trabajo | C19: =TEXT(A19,"dddd") -> viernes | D19: 46143
A20: 46177 | B20: Corpus Christi | C20: =TEXT(A20,"dddd") -> jueves | D20: 46177
A21: 46194 | B21: Año Nuevo Andino Amazónico | C21: =TEXT(A21,"dddd") -> domingo | D21: 21 Jun (domingo, no traslada)
A22: 46240 | B22: Día de la Independencia | C22: =TEXT(A22,"dddd") -> jueves | D22: 6 Ago
A23: 46328 | B23: Todos Santos | C23: =TEXT(A23,"dddd") -> lunes | D23: 2 Nov (lunes; cae do 1 Nov, traslado)
A24: 46381 | B24: Navidad | C24: =TEXT(A24,"dddd") -> viernes | D24: 25 Dic

Sheet Gantt
A1: GANTT – GESTIÓN DOCUMENTAL (Días hábiles — Bolivia 2026) | M1: Línea de tiempo del proyecto — Días hábiles (Bolivia 2026)
A2: Fecha de inicio: | B2: =FechaInicioProyecto -> 46113 | C2: Horizonte (d.h.): | D2: =HorizonteDias -> 84 | E2: Fecha fin: | F2: =Configuración!B7 -> 46233 | J2: % Avance: | K2: {=SUMPRODUCT((L5:L32="Completado")*J5:J32)} -> 0.292 | M2: =IF(M3="","",UPPER(TEXT(M3,"mmm yyyy"))) -> ABR 2026 | N2: =IF(N3="","",IF(OR(M3="",TEXT(N3,"mmm")<>TEXT(M3,"mmm")),UPPER(TEXT(N3,"mmm yyyy")),"")) | O2: =IF(O3="","",IF(OR(N3="",TEXT(O3,"mmm")<>TEXT(N3,"mmm")),UPPER(TEXT(O3,"mmm yyyy")),"")) | P2: =IF(P3="","",IF(OR(O3="",TEXT(P3,"mmm")<>TEXT(O3,"mmm")),UPPER(TEXT(P3,"mmm yyyy")),"")) | Q2: =IF(Q3="","",IF(OR(P3="",TEXT(Q3,"mmm")<>TEXT(P3,"mmm")),UPPER(TEXT(Q3,"mmm yyyy")),"")) | R2: =IF(R3="","",IF(OR(Q3="",TEXT(R3,"mmm")<>TEXT(Q3,"mmm")),UPPER(TEXT(R3,"mmm yyyy")),"")) | S2: =IF(S3="","",IF(OR(R3="",TEXT(S3,"mmm")<>TEXT(R3,"mmm")),UPPER(TEXT(S3,"mmm yyyy")),"")) | T2: =IF(T3="","",IF(OR(S3="",TEXT(T3,"mmm")<>TEXT(S3,"mmm")),UPPER(TEXT(T3,"mmm yyyy")),"")) | U2: =IF(U3="","",IF(OR(T3="",TEXT(U3,"mmm")<>TEXT(T3,"mmm")),UPPER(TEXT(U3,"mmm yyyy")),"")) | ... JL2: =IF(JL3="","",IF(OR(JK3="",TEXT(JL3,"mmm")<>TEXT(JK3,"mmm")),UPPER(TEXT(JL3,"mmm yyyy")),""))
A3: Fase | B3: Actividad | C3: Responsable | D3: Inicio | E3: Días (hábiles) | F3: Fin | G3: Inicio Real | H3: Fin Real | I3: Desviacion | J3: Peso (%) | K3: % Acum. | L3: Estado | M3: =IF(1>HorizonteDias,"",FechaInicioProyecto) -> 46113 | N3: =IF(2>HorizonteDias,"",IFERROR(WORKDAY(M3,1,Feriados_BO_2026),WORKDAY(FechaInicioProyecto,1,Feriados_BO_2026))) -> 46114 | O3: =IF(3>HorizonteDias,"",IFERROR(WORKDAY(N3,1,Feriados_BO_2026),WORKDAY(FechaInicioProyecto,2,Feriados_BO_2026))) -> 46118 | P3: =IF(4>HorizonteDias,"",IFERROR(WORKDAY(O3,1,Feriados_BO_2026),WORKDAY(FechaInicioProyecto,3,Feriados_BO_2026))) -> 46119 | Q3: =IF(5>HorizonteDias,"",IFERROR(WORKDAY(P3,1,Feriados_BO_2026),WORKDAY(FechaInicioProyecto,4,Feriados_BO_2026))) -> 46120 | R3: =IF(6>HorizonteDias,"",IFERROR(WORKDAY(Q3,1,Feriados_BO_2026),WORKDAY(FechaInicioProyecto,5,Feriados_BO_2026))) -> 46121 | S3: =IF(7>HorizonteDias,"",IFERROR(WORKDAY(R3,1,Feriados_BO_2026),WORKDAY(FechaInicioProyecto,6,Feriados_BO_2026))) -> 46122 | T3: =IF(8>HorizonteDias,"",IFERROR(WORKDAY(S3,1,Feriados_BO_2026),WORKDAY(FechaInicioProyecto,7,Feriados_BO_2026))) -> 46125 | U3: =IF(9>HorizonteDias,"",IFERROR(WORKDAY(T3,1,Feriados_BO_2026),WORKDAY(FechaInicioProyecto,8,Feriados_BO_2026))) -> 46126 | V3: =IF(10>HorizonteDias,"",IFERROR(WORKDAY(U3,1,Feriados_BO_2026),WORKDAY(FechaInicioProyecto,9,Feriados_BO_2026))) -> 46127 | W3: =IF(11>HorizonteDias,"",IFERROR(WORKDAY(V3,1,Feriados_BO_2026),WORKDAY(FechaInicioProyecto,10,Feriados_BO_2026))) -> 46128 | X3: =IF(12>HorizonteDias,"",IFERROR(WORKDAY(W3,1,Feriados_BO_2026),WORKDAY(FechaInicioProyecto,11,Feriados_BO_2026))) -> 46129 | Y3: =IF(13>HorizonteDias,"",IFERROR(WORKDAY(X3,1,Feriados_BO_2026),WORKDAY(FechaInicioProyecto,12,Feriados_BO_2026))) -> 46132 | Z3: =IF(14>HorizonteDias,"",IFERROR(WORKDAY(Y3,1,Feriados_BO_2026),WORKDAY(FechaInicioProyecto,13,Feriados_BO_2026))) -> 46133 | AA3: =IF(15>HorizonteDias,"",IFERROR(WORKDAY(Z3,1,Feriados_BO_2026),WORKDAY(FechaInicioProyecto,14,Feriados_BO_2026))) -> 46134 | AB3: =IF(16>HorizonteDias,"",IFERROR(WORKDAY(AA3,1,Feriados_BO_2026),WORKDAY(FechaInicioProyecto,15,Feriados_BO_2026))) -> 46135 | AC3: =IF(17>HorizonteDias,"",IFERROR(WORKDAY(AB3,1,Feriados_BO_2026),WORKDAY(FechaInicioProyecto,16,Feriados_BO_2026))) -> 46136 | AD3: =IF(18>HorizonteDias,"",IFERROR(WORKDAY(AC3,1,Feriados_BO_2026),WORKDAY(FechaInicioProyecto,17,Feriados_BO_2026))) -> 46139 | AE3: =IF(19>HorizonteDias,"",IFERROR(WORKDAY(AD3,1,Feriados_BO_2026),WORKDAY(FechaInicioProyecto,18,Feriados_BO_2026))) -> 46140 | AF3: =IF(20>HorizonteDias,"",IFERROR(WORKDAY(AE3,1,Feriados_BO_2026),WORKDAY(FechaInicioProyecto,19,Feriados_BO_2026))) -> 46141 | AG3: =IF(21>HorizonteDias,"",IFERROR(WORKDAY(AF3,1,Feriados_BO_2026),WORKDAY(FechaInicioProyecto,20,Feriados_BO_2026))) -> 46142 | AH3: =IF(22>HorizonteDias,"",IFERROR(WORKDAY(AG3,1,Feriados_BO_2026),WORKDAY(FechaInicioProyecto,21,Feriados_BO_2026))) -> 46146 | AI3: =IF(23>HorizonteDias,"",IFERROR(WORKDAY(AH3,1,Feriados_BO_2026),WORKDAY(FechaInicioProyecto,22,Feriados_BO_2026))) -> 46147 | AJ3: =IF(24>HorizonteDias,"",IFERROR(WORKDAY(AI3,1,Feriados_BO_2026),WORKDAY(FechaInicioProyecto,23,Feriados_BO_2026))) -> 46148 | AK3: =IF(25>HorizonteDias,"",IFERROR(WORKDAY(AJ3,1,Feriados_BO_2026),WORKDAY(FechaInicioProyecto,24,Feriados_BO_2026))) -> 46149 | AL3: =IF(26>HorizonteDias,"",IFERROR(WORKDAY(AK3,1,Feriados_BO_2026),WORKDAY(FechaInicioProyecto,25,Feriados_BO_2026))) -> 46150 | AM3: =IF(27>HorizonteDias,"",IFERROR(WORKDAY(AL3,1,Feriados_BO_2026),WORKDAY(FechaInicioProyecto,26,Feriados_BO_2026))) -> 46153 | AN3: =IF(28>HorizonteDias,"",IFERROR(WORKDAY(AM3,1,Feriados_BO_2026),WORKDAY(FechaInicioProyecto,27,Feriados_BO_2026))) -> 46154 | AO3: =IF(29>HorizonteDias,"",IFERROR(WORKDAY(AN3,1,Feriados_BO_2026),WORKDAY(FechaInicioProyecto,28,Feriados_BO_2026))) -> 46155 | AP3: =IF(30>HorizonteDias,"",IFERROR(WORKDAY(AO3,1,Feriados_BO_2026),WORKDAY(FechaInicioProyecto,29,Feriados_BO_2026))) -> 46156 | AQ3: =IF(31>HorizonteDias,"",IFERROR(WORKDAY(AP3,1,Feriados_BO_2026),WORKDAY(FechaInicioProyecto,30,Feriados_BO_2026))) -> 46157 | AR3: =IF(32>HorizonteDias,"",IFERROR(WORKDAY(AQ3,1,Feriados_BO_2026),WORKDAY(FechaInicioProyecto,31,Feriados_BO_2026))) -> 46160 | AS3: =IF(33>HorizonteDias,"",IFERROR(WORKDAY(AR3,1,Feriados_BO_2026),WORKDAY(FechaInicioProyecto,32,Feriados_BO_2026))) -> 46161 | AT3: =IF(34>HorizonteDias,"",IFERROR(WORKDAY(AS3,1,Feriados_BO_2026),WORKDAY(FechaInicioProyecto,33,Feriados_BO_2026))) -> 46162 | AU3: =IF(35>HorizonteDias,"",IFERROR(WORKDAY(AT3,1,Feriados_BO_2026),WORKDAY(FechaInicioProyecto,34,Feriados_BO_2026))) -> 46163 | AV3: =IF(36>HorizonteDias,"",IFERROR(WORKDAY(AU3,1,Feriados_BO_2026),WORKDAY(FechaInicioProyecto,35,Feriados_BO_2026))) -> 46164 | AW3: =IF(37>HorizonteDias,"",IFERROR(WORKDAY(AV3,1,Feriados_BO_2026),WORKDAY(FechaInicioProyecto,36,Feriados_BO_2026))) -> 46167 | AX3: =IF(38>HorizonteDias,"",IFERROR(WORKDAY(AW3,1,Feriados_BO_2026),WORKDAY(FechaInicioProyecto,37,Feriados_BO_2026))) -> 46168 | AY3: =IF(39>HorizonteDias,"",IFERROR(WORKDAY(AX3,1,Feriados_BO_2026),WORKDAY(FechaInicioProyecto,38,Feriados_BO_2026))) -> 46169 | AZ3: =IF(40>HorizonteDias,"",IFERROR(WORKDAY(AY3,1,Feriados_BO_2026),WORKDAY(FechaInicioProyecto,39,Feriados_BO_2026))) -> 46170 | BA3: =IF(41>HorizonteDias,"",IFERROR(WORKDAY(AZ3,1,Feriados_BO_2026),WORKDAY(FechaInicioProyecto,40,Feriados_BO_2026))) -> 46171 | BB3: =IF(42>HorizonteDias,"",IFERROR(WORKDAY(BA3,1,Feriados_BO_2026),WORKDAY(FechaInicioProyecto,41,Feriados_BO_2026))) -> 46174 | BC3: =IF(43>HorizonteDias,"",IFERROR(WORKDAY(BB3,1,Feriados_BO_2026),WORKDAY(FechaInicioProyecto,42,Feriados_BO_2026))) -> 46175 | BD3: =IF(44>HorizonteDias,"",IFERROR(WORKDAY(BC3,1,Feriados_BO_2026),WORKDAY(FechaInicioProyecto,43,Feriados_BO_2026))) -> 46176 | BE3: =IF(45>HorizonteDias,"",IFERROR(WORKDAY(BD3,1,Feriados_BO_2026),WORKDAY(FechaInicioProyecto,44,Feriados_BO_2026))) -> 46178 | BF3: =IF(46>HorizonteDias,"",IFERROR(WORKDAY(BE3,1,Feriados_BO_2026),WORKDAY(FechaInicioProyecto,45,Feriados_BO_2026))) -> 46181 | BG3: =IF(47>HorizonteDias,"",IFERROR(WORKDAY(BF3,1,Feriados_BO_2026),WORKDAY(FechaInicioProyecto,46,Feriados_BO_2026))) -> 46182 | BH3: =IF(48>HorizonteDias,"",IFERROR(WORKDAY(BG3,1,Feriados_BO_2026),WORKDAY(FechaInicioProyecto,47,Feriados_BO_2026))) -> 46183 | BI3: =IF(49>HorizonteDias,"",IFERROR(WORKDAY(BH3,1,Feriados_BO_2026),WORKDAY(FechaInicioProyecto,48,Feriados_BO_2026))) -> 46184 | BJ3: =IF(50>HorizonteDias,"",IFERROR(WORKDAY(BI3,1,Feriados_BO_2026),WORKDAY(FechaInicioProyecto,49,Feriados_BO_2026))) -> 46185 | BK3: =IF(51>HorizonteDias,"",IFERROR(WORKDAY(BJ3,1,Feriados_BO_2026),WORKDAY(FechaInicioProyecto,50,Feriados_BO_2026))) -> 46188 | BL3: =IF(52>HorizonteDias,"",IFERROR(WORKDAY(BK3,1,Feriados_BO_2026),WORKDAY(FechaInicioProyecto,51,Feriados_BO_2026))) -> 46189 | BM3: =IF(53>HorizonteDias,"",IFERROR(WORKDAY(BL3,1,Feriados_BO_2026),WORKDAY(FechaInicioProyecto,52,Feriados_BO_2026))) -> 46190 | BN3: =IF(54>HorizonteDias,"",IFERROR(WORKDAY(BM3,1,Feriados_BO_2026),WORKDAY(FechaInicioProyecto,53,Feriados_BO_2026))) -> 46191 | BO3: =IF(55>HorizonteDias,"",IFERROR(WORKDAY(BN3,1,Feriados_BO_2026),WORKDAY(FechaInicioProyecto,54,Feriados_BO_2026))) -> 46192 | BP3: =IF(56>HorizonteDias,"",IFERROR(WORKDAY(BO3,1,Feriados_BO_2026),WORKDAY(FechaInicioProyecto,55,Feriados_BO_2026))) -> 46195 | BQ3: =IF(57>HorizonteDias,"",IFERROR(WORKDAY(BP3,1,Feriados_BO_2026),WORKDAY(FechaInicioProyecto,56,Feriados_BO_2026))) -> 46196 | BR3: =IF(58>HorizonteDias,"",IFERROR(WORKDAY(BQ3,1,Feriados_BO_2026),WORKDAY(FechaInicioProyecto,57,Feriados_BO_2026))) -> 46197 | BS3: =IF(59>HorizonteDias,"",IFERROR(WORKDAY(BR3,1,Feriados_BO_2026),WORKDAY(FechaInicioProyecto,58,Feriados_BO_2026))) -> 46198 | BT3: =IF(60>HorizonteDias,"",IFERROR(WORKDAY(BS3,1,Feriados_BO_2026),WORKDAY(FechaInicioProyecto,59,Feriados_BO_2026))) -> 46199 | BU3: =IF(61>HorizonteDias,"",IFERROR(WORKDAY(BT3,1,Feriados_BO_2026),WORKDAY(FechaInicioProyecto,60,Feriados_BO_2026))) -> 46202 | BV3: =IF(62>HorizonteDias,"",IFERROR(WORKDAY(BU3,1,Feriados_BO_2026),WORKDAY(FechaInicioProyecto,61,Feriados_BO_2026))) -> 46203 | BW3: =IF(63>HorizonteDias,"",IFERROR(WORKDAY(BV3,1,Feriados_BO_2026),WORKDAY(FechaInicioProyecto,62,Feriados_BO_2026))) -> 46204 | BX3: =IF(64>HorizonteDias,"",IFERROR(WORKDAY(BW3,1,Feriados_BO_2026),WORKDAY(FechaInicioProyecto,63,Feriados_BO_2026))) -> 46205 | BY3: =IF(65>HorizonteDias,"",IFERROR(WORKDAY(BX3,1,Feriados_BO_2026),WORKDAY(FechaInicioProyecto,64,Feriados_BO_2026))) -> 46206 | BZ3: =IF(66>HorizonteDias,"",IFERROR(WORKDAY(BY3,1,Feriados_BO_2026),WORKDAY(FechaInicioProyecto,65,Feriados_BO_2026))) -> 46209 | CA3: =IF(67>HorizonteDias,"",IFERROR(WORKDAY(BZ3,1,Feriados_BO_2026),WORKDAY(FechaInicioProyecto,66,Feriados_BO_2026))) -> 46210 | CB3: =IF(68>HorizonteDias,"",IFERROR(WORKDAY(CA3,1,Feriados_BO_2026),WORKDAY(FechaInicioProyecto,67,Feriados_BO_2026))) -> 46211 | CC3: =IF(69>HorizonteDias,"",IFERROR(WORKDAY(CB3,1,Feriados_BO_2026),WORKDAY(FechaInicioProyecto,68,Feriados_BO_2026))) -> 46212 | CD3: =IF(70>HorizonteDias,"",IFERROR(WORKDAY(CC3,1,Feriados_BO_2026),WORKDAY(FechaInicioProyecto,69,Feriados_BO_2026))) -> 46213 | CE3: =IF(71>HorizonteDias,"",IFERROR(WORKDAY(CD3,1,Feriados_BO_2026),WORKDAY(FechaInicioProyecto,70,Feriados_BO_2026))) -> 46216 | CF3: =IF(72>HorizonteDias,"",IFERROR(WORKDAY(CE3,1,Feriados_BO_2026),WORKDAY(FechaInicioProyecto,71,Feriados_BO_2026))) -> 46217 | CG3: =IF(73>HorizonteDias,"",IFERROR(WORKDAY(CF3,1,Feriados_BO_2026),WORKDAY(FechaInicioProyecto,72,Feriados_BO_2026))) -> 46218 | CH3: =IF(74>HorizonteDias,"",IFERROR(WORKDAY(CG3,1,Feriados_BO_2026),WORKDAY(FechaInicioProyecto,73,Feriados_BO_2026))) -> 46219 | CI3: =IF(75>HorizonteDias,"",IFERROR(WORKDAY(CH3,1,Feriados_BO_2026),WORKDAY(FechaInicioProyecto,74,Feriados_BO_2026))) -> 46220 | CJ3: =IF(76>HorizonteDias,"",IFERROR(WORKDAY(CI3,1,Feriados_BO_2026),WORKDAY(FechaInicioProyecto,75,Feriados_BO_2026))) -> 46223 | CK3: =IF(77>HorizonteDias,"",IFERROR(WORKDAY(CJ3,1,Feriados_BO_2026),WORKDAY(FechaInicioProyecto,76,Feriados_BO_2026))) -> 46224 | CL3: =IF(78>HorizonteDias,"",IFERROR(WORKDAY(CK3,1,Feriados_BO_2026),WORKDAY(FechaInicioProyecto,77,Feriados_BO_2026))) -> 46225 | CM3: =IF(79>HorizonteDias,"",IFERROR(WORKDAY(CL3,1,Feriados_BO_2026),WORKDAY(FechaInicioProyecto,78,Feriados_BO_2026))) -> 46226 | CN3: =IF(80>HorizonteDias,"",IFERROR(WORKDAY(CM3,1,Feriados_BO_2026),WORKDAY(FechaInicioProyecto,79,Feriados_BO_2026))) -> 46227 | CO3: =IF(81>HorizonteDias,"",IFERROR(WORKDAY(CN3,1,Feriados_BO_2026),WORKDAY(FechaInicioProyecto,80,Feriados_BO_2026))) -> 46230 | CP3: =IF(82>HorizonteDias,"",IFERROR(WORKDAY(CO3,1,Feriados_BO_2026),WORKDAY(FechaInicioProyecto,81,Feriados_BO_2026))) -> 46231 | CQ3: =IF(83>HorizonteDias,"",IFERROR(WORKDAY(CP3,1,Feriados_BO_2026),WORKDAY(FechaInicioProyecto,82,Feriados_BO_2026))) -> 46232 | CR3: =IF(84>HorizonteDias,"",IFERROR(WORKDAY(CQ3,1,Feriados_BO_2026),WORKDAY(FechaInicioProyecto,83,Feriados_BO_2026))) -> 46233 | CS3: =IF(85>HorizonteDias,"",IFERROR(WORKDAY(CR3,1,Feriados_BO_2026),WORKDAY(FechaInicioProyecto,84,Feriados_BO_2026))) | CT3: =IF(86>HorizonteDias,"",IFERROR(WORKDAY(CS3,1,Feriados_BO_2026),WORKDAY(FechaInicioProyecto,85,Feriados_BO_2026))) | CU3: =IF(87>HorizonteDias,"",IFERROR(WORKDAY(CT3,1,Feriados_BO_2026),WORKDAY(FechaInicioProyecto,86,Feriados_BO_2026))) | CV3: =IF(88>HorizonteDias,"",IFERROR(WORKDAY(CU3,1,Feriados_BO_2026),WORKDAY(FechaInicioProyecto,87,Feriados_BO_2026))) | CW3: =IF(89>HorizonteDias,"",IFERROR(WORKDAY(CV3,1,Feriados_BO_2026),WORKDAY(FechaInicioProyecto,88,Feriados_BO_2026))) | CX3: =IF(90>HorizonteDias,"",IFERROR(WORKDAY(CW3,1,Feriados_BO_2026),WORKDAY(FechaInicioProyecto,89,Feriados_BO_2026))) | CY3: =IF(91>HorizonteDias,"",IFERROR(WORKDAY(CX3,1,Feriados_BO_2026),WORKDAY(FechaInicioProyecto,90,Feriados_BO_2026))) | CZ3: =IF(92>HorizonteDias,"",IFERROR(WORKDAY(CY3,1,Feriados_BO_2026),WORKDAY(FechaInicioProyecto,91,Feriados_BO_2026))) | DA3: =IF(93>HorizonteDias,"",IFERROR(WORKDAY(CZ3,1,Feriados_BO_2026),WORKDAY(FechaInicioProyecto,92,Feriados_BO_2026))) | DB3: =IF(94>HorizonteDias,"",IFERROR(WORKDAY(DA3,1,Feriados_BO_2026),WORKDAY(FechaInicioProyecto,93,Feriados_BO_2026))) | DC3: =IF(95>HorizonteDias,"",IFERROR(WORKDAY(DB3,1,Feriados_BO_2026),WORKDAY(FechaInicioProyecto,94,Feriados_BO_2026))) | DD3: =IF(96>HorizonteDias,"",IFERROR(WORKDAY(DC3,1,Feriados_BO_2026),WORKDAY(FechaInicioProyecto,95,Feriados_BO_2026))) | DE3: =IF(97>HorizonteDias,"",IFERROR(WORKDAY(DD3,1,Feriados_BO_2026),WORKDAY(FechaInicioProyecto,96,Feriados_BO_2026))) | DF3: =IF(98>HorizonteDias,"",IFERROR(WORKDAY(DE3,1,Feriados_BO_2026),WORKDAY(FechaInicioProyecto,97,Feriados_BO_2026))) | DG3: =IF(99>HorizonteDias,"",IFERROR(WORKDAY(DF3,1,Feriados_BO_2026),WORKDAY(FechaInicioProyecto,98,Feriados_BO_2026))) | DH3: =IF(100>HorizonteDias,"",IFERROR(WORKDAY(DG3,1,Feriados_BO_2026),WORKDAY(FechaInicioProyecto,99,Feriados_BO_2026))) | DI3: =IF(101>HorizonteDias,"",IFERROR(WORKDAY(DH3,1,Feriados_BO_2026),WORKDAY(FechaInicioProyecto,100,Feriados_BO_2026))) | DJ3: =IF(102>HorizonteDias,"",IFERROR(WORKDAY(DI3,1,Feriados_BO_2026),WORKDAY(FechaInicioProyecto,101,Feriados_BO_2026))) | DK3: =IF(103>HorizonteDias,"",IFERROR(WORKDAY(DJ3,1,Feriados_BO_2026),WORKDAY(FechaInicioProyecto,102,Feriados_BO_2026))) | DL3: =IF(104>HorizonteDias,"",IFERROR(WORKDAY(DK3,1,Feriados_BO_2026),WORKDAY(FechaInicioProyecto,103,Feriados_BO_2026))) | DM3: =IF(105>HorizonteDias,"",IFERROR(WORKDAY(DL3,1,Feriados_BO_2026),WORKDAY(FechaInicioProyecto,104,Feriados_BO_2026))) | DN3: =IF(106>HorizonteDias,"",IFERROR(WORKDAY(DM3,1,Feriados_BO_2026),WORKDAY(FechaInicioProyecto,105,Feriados_BO_2026))) | DO3: =IF(107>HorizonteDias,"",IFERROR(WORKDAY(DN3,1,Feriados_BO_2026),WORKDAY(FechaInicioProyecto,106,Feriados_BO_2026))) | DP3: =IF(108>HorizonteDias,"",IFERROR(WORKDAY(DO3,1,Feriados_BO_2026),WORKDAY(FechaInicioProyecto,107,Feriados_BO_2026))) | DQ3: =IF(109>HorizonteDias,"",IFERROR(WORKDAY(DP3,1,Feriados_BO_2026),WORKDAY(FechaInicioProyecto,108,Feriados_BO_2026))) | DR3: =IF(110>HorizonteDias,"",IFERROR(WORKDAY(DQ3,1,Feriados_BO_2026),WORKDAY(FechaInicioProyecto,109,Feriados_BO_2026))) | DS3: =IF(111>HorizonteDias,"",IFERROR(WORKDAY(DR3,1,Feriados_BO_2026),WORKDAY(FechaInicioProyecto,110,Feriados_BO_2026))) | DT3: =IF(112>HorizonteDias,"",IFERROR(WORKDAY(DS3,1,Feriados_BO_2026),WORKDAY(FechaInicioProyecto,111,Feriados_BO_2026))) | DU3: =IF(113>HorizonteDias,"",IFERROR(WORKDAY(DT3,1,Feriados_BO_2026),WORKDAY(FechaInicioProyecto,112,Feriados_BO_2026))) | DV3: =IF(114>HorizonteDias,"",IFERROR(WORKDAY(DU3,1,Feriados_BO_2026),WORKDAY(FechaInicioProyecto,113,Feriados_BO_2026))) | DW3: =IF(115>HorizonteDias,"",IFERROR(WORKDAY(DV3,1,Feriados_BO_2026),WORKDAY(FechaInicioProyecto,114,Feriados_BO_2026))) | DX3: =IF(116>HorizonteDias,"",IFERROR(WORKDAY(DW3,1,Feriados_BO_2026),WORKDAY(FechaInicioProyecto,115,Feriados_BO_2026))) | DY3: =IF(117>HorizonteDias,"",IFERROR(WORKDAY(DX3,1,Feriados_BO_2026),WORKDAY(FechaInicioProyecto,116,Feriados_BO_2026))) | DZ3: =IF(118>HorizonteDias,"",IFERROR(WORKDAY(DY3,1,Feriados_BO_2026),WORKDAY(FechaInicioProyecto,117,Feriados_BO_2026))) | EA3: =IF(119>HorizonteDias,"",IFERROR(WORKDAY(DZ3,1,Feriados_BO_2026),WORKDAY(FechaInicioProyecto,118,Feriados_BO_2026))) | EB3: =IF(120>HorizonteDias,"",IFERROR(WORKDAY(EA3,1,Feriados_BO_2026),WORKDAY(FechaInicioProyecto,119,Feriados_BO_2026))) | EC3: =IF(121>HorizonteDias,"",IFERROR(WORKDAY(EB3,1,Feriados_BO_2026),WORKDAY(FechaInicioProyecto,120,Feriados_BO_2026))) | ED3: =IF(122>HorizonteDias,"",IFERROR(WORKDAY(EC3,1,Feriados_BO_2026),WORKDAY(FechaInicioProyecto,121,Feriados_BO_2026))) | EE3: =IF(123>HorizonteDias,"",IFERROR(WORKDAY(ED3,1,Feriados_BO_2026),WORKDAY(FechaInicioProyecto,122,Feriados_BO_2026))) | EF3: =IF(124>HorizonteDias,"",IFERROR(WORKDAY(EE3,1,Feriados_BO_2026),WORKDAY(FechaInicioProyecto,123,Feriados_BO_2026))) | EG3: =IF(125>HorizonteDias,"",IFERROR(WORKDAY(EF3,1,Feriados_BO_2026),WORKDAY(FechaInicioProyecto,124,Feriados_BO_2026))) | EH3: =IF(126>HorizonteDias,"",IFERROR(WORKDAY(EG3,1,Feriados_BO_2026),WORKDAY(FechaInicioProyecto,125,Feriados_BO_2026))) | EI3: =IF(127>HorizonteDias,"",IFERROR(WORKDAY(EH3,1,Feriados_BO_2026),WORKDAY(FechaInicioProyecto,126,Feriados_BO_2026))) | EJ3: =IF(128>HorizonteDias,"",IFERROR(WORKDAY(EI3,1,Feriados_BO_2026),WORKDAY(FechaInicioProyecto,127,Feriados_BO_2026))) | EK3: =IF(129>HorizonteDias,"",IFERROR(WORKDAY(EJ3,1,Feriados_BO_2026),WORKDAY(FechaInicioProyecto,128,Feriados_BO_2026))) | EL3: =IF(130>HorizonteDias,"",IFERROR(WORKDAY(EK3,1,Feriados_BO_2026),WORKDAY(FechaInicioProyecto,129,Feriados_BO_2026))) | EM3: =IF(131>HorizonteDias,"",IFERROR(WORKDAY(EL3,1,Feriados_BO_2026),WORKDAY(FechaInicioProyecto,130,Feriados_BO_2026))) | EN3: =IF(132>HorizonteDias,"",IFERROR(WORKDAY(EM3,1,Feriados_BO_2026),WORKDAY(FechaInicioProyecto,131,Feriados_BO_2026))) | EO3: =IF(133>HorizonteDias,"",IFERROR(WORKDAY(EN3,1,Feriados_BO_2026),WORKDAY(FechaInicioProyecto,132,Feriados_BO_2026))) | EP3: =IF(134>HorizonteDias,"",IFERROR(WORKDAY(EO3,1,Feriados_BO_2026),WORKDAY(FechaInicioProyecto,133,Feriados_BO_2026))) | EQ3: =IF(135>HorizonteDias,"",IFERROR(WORKDAY(EP3,1,Feriados_BO_2026),WORKDAY(FechaInicioProyecto,134,Feriados_BO_2026))) | ER3: =IF(136>HorizonteDias,"",IFERROR(WORKDAY(EQ3,1,Feriados_BO_2026),WORKDAY(FechaInicioProyecto,135,Feriados_BO_2026))) | ES3: =IF(137>HorizonteDias,"",IFERROR(WORKDAY(ER3,1,Feriados_BO_2026),WORKDAY(FechaInicioProyecto,136,Feriados_BO_2026))) | ET3: =IF(138>HorizonteDias,"",IFERROR(WORKDAY(ES3,1,Feriados_BO_2026),WORKDAY(FechaInicioProyecto,137,Feriados_BO_2026))) | EU3: =IF(139>HorizonteDias,"",IFERROR(WORKDAY(ET3,1,Feriados_BO_2026),WORKDAY(FechaInicioProyecto,138,Feriados_BO_2026))) | EV3: =IF(140>HorizonteDias,"",IFERROR(WORKDAY(EU3,1,Feriados_BO_2026),WORKDAY(FechaInicioProyecto,139,Feriados_BO_2026))) | EW3: =IF(141>HorizonteDias,"",IFERROR(WORKDAY(EV3,1,Feriados_BO_2026),WORKDAY(FechaInicioProyecto,140,Feriados_BO_2026))) | EX3: =IF(142>HorizonteDias,"",IFERROR(WORKDAY(EW3,1,Feriados_BO_2026),WORKDAY(FechaInicioProyecto,141,Feriados_BO_2026))) | EY3: =IF(143>HorizonteDias,"",IFERROR(WORKDAY(EX3,1,Feriados_BO_2026),WORKDAY(FechaInicioProyecto,142,Feriados_BO_2026))) | EZ3: =IF(144>HorizonteDias,"",IFERROR(WORKDAY(EY3,1,Feriados_BO_2026),WORKDAY(FechaInicioProyecto,143,Feriados_BO_2026))) | FA3: =IF(145>HorizonteDias,"",IFERROR(WORKDAY(EZ3,1,Feriados_BO_2026),WORKDAY(FechaInicioProyecto,144,Feriados_BO_2026))) | FB3: =IF(146>HorizonteDias,"",IFERROR(WORKDAY(FA3,1,Feriados_BO_2026),WORKDAY(FechaInicioProyecto,145,Feriados_BO_2026))) | FC3: =IF(147>HorizonteDias,"",IFERROR(WORKDAY(FB3,1,Feriados_BO_2026),WORKDAY(FechaInicioProyecto,146,Feriados_BO_2026))) | FD3: =IF(148>HorizonteDias,"",IFERROR(WORKDAY(FC3,1,Feriados_BO_2026),WORKDAY(FechaInicioProyecto,147,Feriados_BO_2026))) | FE3: =IF(149>HorizonteDias,"",IFERROR(WORKDAY(FD3,1,Feriados_BO_2026),WORKDAY(FechaInicioProyecto,148,Feriados_BO_2026))) | FF3: =IF(150>HorizonteDias,"",IFERROR(WORKDAY(FE3,1,Feriados_BO_2026),WORKDAY(FechaInicioProyecto,149,Feriados_BO_2026))) | FG3: =IF(151>HorizonteDias,"",IFERROR(WORKDAY(FF3,1,Feriados_BO_2026),WORKDAY(FechaInicioProyecto,150,Feriados_BO_2026))) | FH3: =IF(152>HorizonteDias,"",IFERROR(WORKDAY(FG3,1,Feriados_BO_2026),WORKDAY(FechaInicioProyecto,151,Feriados_BO_2026))) | FI3: =IF(153>HorizonteDias,"",IFERROR(WORKDAY(FH3,1,Feriados_BO_2026),WORKDAY(FechaInicioProyecto,152,Feriados_BO_2026))) | FJ3: =IF(154>HorizonteDias,"",IFERROR(WORKDAY(FI3,1,Feriados_BO_2026),WORKDAY(FechaInicioProyecto,153,Feriados_BO_2026))) | FK3: =IF(155>HorizonteDias,"",IFERROR(WORKDAY(FJ3,1,Feriados_BO_2026),WORKDAY(FechaInicioProyecto,154,Feriados_BO_2026))) | FL3: =IF(156>HorizonteDias,"",IFERROR(WORKDAY(FK3,1,Feriados_BO_2026),WORKDAY(FechaInicioProyecto,155,Feriados_BO_2026))) | FM3: =IF(157>HorizonteDias,"",IFERROR(WORKDAY(FL3,1,Feriados_BO_2026),WORKDAY(FechaInicioProyecto,156,Feriados_BO_2026))) | FN3: =IF(158>HorizonteDias,"",IFERROR(WORKDAY(FM3,1,Feriados_BO_2026),WORKDAY(FechaInicioProyecto,157,Feriados_BO_2026))) | FO3: =IF(159>HorizonteDias,"",IFERROR(WORKDAY(FN3,1,Feriados_BO_2026),WORKDAY(FechaInicioProyecto,158,Feriados_BO_2026))) | FP3: =IF(160>HorizonteDias,"",IFERROR(WORKDAY(FO3,1,Feriados_BO_2026),WORKDAY(FechaInicioProyecto,159,Feriados_BO_2026))) | FQ3: =IF(161>HorizonteDias,"",IFERROR(WORKDAY(FP3,1,Feriados_BO_2026),WORKDAY(FechaInicioProyecto,160,Feriados_BO_2026))) | FR3: =IF(162>HorizonteDias,"",IFERROR(WORKDAY(FQ3,1,Feriados_BO_2026),WORKDAY(FechaInicioProyecto,161,Feriados_BO_2026))) | FS3: =IF(163>HorizonteDias,"",IFERROR(WORKDAY(FR3,1,Feriados_BO_2026),WORKDAY(FechaInicioProyecto,162,Feriados_BO_2026))) | FT3: =IF(164>HorizonteDias,"",IFERROR(WORKDAY(FS3,1,Feriados_BO_2026),WORKDAY(FechaInicioProyecto,163,Feriados_BO_2026))) | FU3: =IF(165>HorizonteDias,"",IFERROR(WORKDAY(FT3,1,Feriados_BO_2026),WORKDAY(FechaInicioProyecto,164,Feriados_BO_2026))) | FV3: =IF(166>HorizonteDias,"",IFERROR(WORKDAY(FU3,1,Feriados_BO_2026),WORKDAY(FechaInicioProyecto,165,Feriados_BO_2026))) | FW3: =IF(167>HorizonteDias,"",IFERROR(WORKDAY(FV3,1,Feriados_BO_2026),WORKDAY(FechaInicioProyecto,166,Feriados_BO_2026))) | FX3: =IF(168>HorizonteDias,"",IFERROR(WORKDAY(FW3,1,Feriados_BO_2026),WORKDAY(FechaInicioProyecto,167,Feriados_BO_2026))) | FY3: =IF(169>HorizonteDias,"",IFERROR(WORKDAY(FX3,1,Feriados_BO_2026),WORKDAY(FechaInicioProyecto,168,Feriados_BO_2026))) | FZ3: =IF(170>HorizonteDias,"",IFERROR(WORKDAY(FY3,1,Feriados_BO_2026),WORKDAY(FechaInicioProyecto,169,Feriados_BO_2026))) | GA3: =IF(171>HorizonteDias,"",IFERROR(WORKDAY(FZ3,1,Feriados_BO_2026),WORKDAY(FechaInicioProyecto,170,Feriados_BO_2026))) | GB3: =IF(172>HorizonteDias,"",IFERROR(WORKDAY(GA3,1,Feriados_BO_2026),WORKDAY(FechaInicioProyecto,171,Feriados_BO_2026))) | GC3: =IF(173>HorizonteDias,"",IFERROR(WORKDAY(GB3,1,Feriados_BO_2026),WORKDAY(FechaInicioProyecto,172,Feriados_BO_2026))) | GD3: =IF(174>HorizonteDias,"",IFERROR(WORKDAY(GC3,1,Feriados_BO_2026),WORKDAY(FechaInicioProyecto,173,Feriados_BO_2026))) | GE3: =IF(175>HorizonteDias,"",IFERROR(WORKDAY(GD3,1,Feriados_BO_2026),WORKDAY(FechaInicioProyecto,174,Feriados_BO_2026))) | GF3: =IF(176>HorizonteDias,"",IFERROR(WORKDAY(GE3,1,Feriados_BO_2026),WORKDAY(FechaInicioProyecto,175,Feriados_BO_2026))) | GG3: =IF(177>HorizonteDias,"",IFERROR(WORKDAY(GF3,1,Feriados_BO_2026),WORKDAY(FechaInicioProyecto,176,Feriados_BO_2026))) | GH3: =IF(178>HorizonteDias,"",IFERROR(WORKDAY(GG3,1,Feriados_BO_2026),WORKDAY(FechaInicioProyecto,177,Feriados_BO_2026))) | GI3: =IF(179>HorizonteDias,"",IFERROR(WORKDAY(GH3,1,Feriados_BO_2026),WORKDAY(FechaInicioProyecto,178,Feriados_BO_2026))) | GJ3: =IF(180>HorizonteDias,"",IFERROR(WORKDAY(GI3,1,Feriados_BO_2026),WORKDAY(FechaInicioProyecto,179,Feriados_BO_2026))) | GK3: =IF(181>HorizonteDias,"",IFERROR(WORKDAY(GJ3,1,Feriados_BO_2026),WORKDAY(FechaInicioProyecto,180,Feriados_BO_2026))) | GL3: =IF(182>HorizonteDias,"",IFERROR(WORKDAY(GK3,1,Feriados_BO_2026),WORKDAY(FechaInicioProyecto,181,Feriados_BO_2026))) | GM3: =IF(183>HorizonteDias,"",IFERROR(WORKDAY(GL3,1,Feriados_BO_2026),WORKDAY(FechaInicioProyecto,182,Feriados_BO_2026))) | GN3: =IF(184>HorizonteDias,"",IFERROR(WORKDAY(GM3,1,Feriados_BO_2026),WORKDAY(FechaInicioProyecto,183,Feriados_BO_2026))) | GO3: =IF(185>HorizonteDias,"",IFERROR(WORKDAY(GN3,1,Feriados_BO_2026),WORKDAY(FechaInicioProyecto,184,Feriados_BO_2026))) | GP3: =IF(186>HorizonteDias,"",IFERROR(WORKDAY(GO3,1,Feriados_BO_2026),WORKDAY(FechaInicioProyecto,185,Feriados_BO_2026))) | GQ3: =IF(187>HorizonteDias,"",IFERROR(WORKDAY(GP3,1,Feriados_BO_2026),WORKDAY(FechaInicioProyecto,186,Feriados_BO_2026))) | GR3: =IF(188>HorizonteDias,"",IFERROR(WORKDAY(GQ3,1,Feriados_BO_2026),WORKDAY(FechaInicioProyecto,187,Feriados_BO_2026))) | GS3: =IF(189>HorizonteDias,"",IFERROR(WORKDAY(GR3,1,Feriados_BO_2026),WORKDAY(FechaInicioProyecto,188,Feriados_BO_2026))) | GT3: =IF(190>HorizonteDias,"",IFERROR(WORKDAY(GS3,1,Feriados_BO_2026),WORKDAY(FechaInicioProyecto,189,Feriados_BO_2026))) | GU3: =IF(191>HorizonteDias,"",IFERROR(WORKDAY(GT3,1,Feriados_BO_2026),WORKDAY(FechaInicioProyecto,190,Feriados_BO_2026))) | GV3: =IF(192>HorizonteDias,"",IFERROR(WORKDAY(GU3,1,Feriados_BO_2026),WORKDAY(FechaInicioProyecto,191,Feriados_BO_2026))) | GW3: =IF(193>HorizonteDias,"",IFERROR(WORKDAY(GV3,1,Feriados_BO_2026),WORKDAY(FechaInicioProyecto,192,Feriados_BO_2026))) | GX3: =IF(194>HorizonteDias,"",IFERROR(WORKDAY(GW3,1,Feriados_BO_2026),WORKDAY(FechaInicioProyecto,193,Feriados_BO_2026))) | GY3: =IF(195>HorizonteDias,"",IFERROR(WORKDAY(GX3,1,Feriados_BO_2026),WORKDAY(FechaInicioProyecto,194,Feriados_BO_2026))) | GZ3: =IF(196>HorizonteDias,"",IFERROR(WORKDAY(GY3,1,Feriados_BO_2026),WORKDAY(FechaInicioProyecto,195,Feriados_BO_2026))) | HA3: =IF(197>HorizonteDias,"",IFERROR(WORKDAY(GZ3,1,Feriados_BO_2026),WORKDAY(FechaInicioProyecto,196,Feriados_BO_2026))) | HB3: =IF(198>HorizonteDias,"",IFERROR(WORKDAY(HA3,1,Feriados_BO_2026),WORKDAY(FechaInicioProyecto,197,Feriados_BO_2026))) | HC3: =IF(199>HorizonteDias,"",IFERROR(WORKDAY(HB3,1,Feriados_BO_2026),WORKDAY(FechaInicioProyecto,198,Feriados_BO_2026))) | HD3: =IF(200>HorizonteDias,"",IFERROR(WORKDAY(HC3,1,Feriados_BO_2026),WORKDAY(FechaInicioProyecto,199,Feriados_BO_2026))) | HE3: =IF(201>HorizonteDias,"",IFERROR(WORKDAY(HD3,1,Feriados_BO_2026),WORKDAY(FechaInicioProyecto,200,Feriados_BO_2026))) | HF3: =IF(202>HorizonteDias,"",IFERROR(WORKDAY(HE3,1,Feriados_BO_2026),WORKDAY(FechaInicioProyecto,201,Feriados_BO_2026))) | HG3: =IF(203>HorizonteDias,"",IFERROR(WORKDAY(HF3,1,Feriados_BO_2026),WORKDAY(FechaInicioProyecto,202,Feriados_BO_2026))) | HH3: =IF(204>HorizonteDias,"",IFERROR(WORKDAY(HG3,1,Feriados_BO_2026),WORKDAY(FechaInicioProyecto,203,Feriados_BO_2026))) | HI3: =IF(205>HorizonteDias,"",IFERROR(WORKDAY(HH3,1,Feriados_BO_2026),WORKDAY(FechaInicioProyecto,204,Feriados_BO_2026))) | HJ3: =IF(206>HorizonteDias,"",IFERROR(WORKDAY(HI3,1,Feriados_BO_2026),WORKDAY(FechaInicioProyecto,205,Feriados_BO_2026))) | HK3: =IF(207>HorizonteDias,"",IFERROR(WORKDAY(HJ3,1,Feriados_BO_2026),WORKDAY(FechaInicioProyecto,206,Feriados_BO_2026))) | HL3: =IF(208>HorizonteDias,"",IFERROR(WORKDAY(HK3,1,Feriados_BO_2026),WORKDAY(FechaInicioProyecto,207,Feriados_BO_2026))) | HM3: =IF(209>HorizonteDias,"",IFERROR(WORKDAY(HL3,1,Feriados_BO_2026),WORKDAY(FechaInicioProyecto,208,Feriados_BO_2026))) | HN3: =IF(210>HorizonteDias,"",IFERROR(WORKDAY(HM3,1,Feriados_BO_2026),WORKDAY(FechaInicioProyecto,209,Feriados_BO_2026))) | HO3: =IF(211>HorizonteDias,"",IFERROR(WORKDAY(HN3,1,Feriados_BO_2026),WORKDAY(FechaInicioProyecto,210,Feriados_BO_2026))) | HP3: =IF(212>HorizonteDias,"",IFERROR(WORKDAY(HO3,1,Feriados_BO_2026),WORKDAY(FechaInicioProyecto,211,Feriados_BO_2026))) | HQ3: =IF(213>HorizonteDias,"",IFERROR(WORKDAY(HP3,1,Feriados_BO_2026),WORKDAY(FechaInicioProyecto,212,Feriados_BO_2026))) | HR3: =IF(214>HorizonteDias,"",IFERROR(WORKDAY(HQ3,1,Feriados_BO_2026),WORKDAY(FechaInicioProyecto,213,Feriados_BO_2026))) | HS3: =IF(215>HorizonteDias,"",IFERROR(WORKDAY(HR3,1,Feriados_BO_2026),WORKDAY(FechaInicioProyecto,214,Feriados_BO_2026))) | HT3: =IF(216>HorizonteDias,"",IFERROR(WORKDAY(HS3,1,Feriados_BO_2026),WORKDAY(FechaInicioProyecto,215,Feriados_BO_2026))) | HU3: =IF(217>HorizonteDias,"",IFERROR(WORKDAY(HT3,1,Feriados_BO_2026),WORKDAY(FechaInicioProyecto,216,Feriados_BO_2026))) | HV3: =IF(218>HorizonteDias,"",IFERROR(WORKDAY(HU3,1,Feriados_BO_2026),WORKDAY(FechaInicioProyecto,217,Feriados_BO_2026))) | HW3: =IF(219>HorizonteDias,"",IFERROR(WORKDAY(HV3,1,Feriados_BO_2026),WORKDAY(FechaInicioProyecto,218,Feriados_BO_2026))) | HX3: =IF(220>HorizonteDias,"",IFERROR(WORKDAY(HW3,1,Feriados_BO_2026),WORKDAY(FechaInicioProyecto,219,Feriados_BO_2026))) | HY3: =IF(221>HorizonteDias,"",IFERROR(WORKDAY(HX3,1,Feriados_BO_2026),WORKDAY(FechaInicioProyecto,220,Feriados_BO_2026))) | HZ3: =IF(222>HorizonteDias,"",IFERROR(WORKDAY(HY3,1,Feriados_BO_2026),WORKDAY(FechaInicioProyecto,221,Feriados_BO_2026))) | IA3: =IF(223>HorizonteDias,"",IFERROR(WORKDAY(HZ3,1,Feriados_BO_2026),WORKDAY(FechaInicioProyecto,222,Feriados_BO_2026))) | IB3: =IF(224>HorizonteDias,"",IFERROR(WORKDAY(IA3,1,Feriados_BO_2026),WORKDAY(FechaInicioProyecto,223,Feriados_BO_2026))) | IC3: =IF(225>HorizonteDias,"",IFERROR(WORKDAY(IB3,1,Feriados_BO_2026),WORKDAY(FechaInicioProyecto,224,Feriados_BO_2026))) | ID3: =IF(226>HorizonteDias,"",IFERROR(WORKDAY(IC3,1,Feriados_BO_2026),WORKDAY(FechaInicioProyecto,225,Feriados_BO_2026))) | IE3: =IF(227>HorizonteDias,"",IFERROR(WORKDAY(ID3,1,Feriados_BO_2026),WORKDAY(FechaInicioProyecto,226,Feriados_BO_2026))) | IF3: =IF(228>HorizonteDias,"",IFERROR(WORKDAY(IE3,1,Feriados_BO_2026),WORKDAY(FechaInicioProyecto,227,Feriados_BO_2026))) | IG3: =IF(229>HorizonteDias,"",IFERROR(WORKDAY(IF3,1,Feriados_BO_2026),WORKDAY(FechaInicioProyecto,228,Feriados_BO_2026))) | IH3: =IF(230>HorizonteDias,"",IFERROR(WORKDAY(IG3,1,Feriados_BO_2026),WORKDAY(FechaInicioProyecto,229,Feriados_BO_2026))) | II3: =IF(231>HorizonteDias,"",IFERROR(WORKDAY(IH3,1,Feriados_BO_2026),WORKDAY(FechaInicioProyecto,230,Feriados_BO_2026))) | IJ3: =IF(232>HorizonteDias,"",IFERROR(WORKDAY(II3,1,Feriados_BO_2026),WORKDAY(FechaInicioProyecto,231,Feriados_BO_2026))) | IK3: =IF(233>HorizonteDias,"",IFERROR(WORKDAY(IJ3,1,Feriados_BO_2026),WORKDAY(FechaInicioProyecto,232,Feriados_BO_2026))) | IL3: =IF(234>HorizonteDias,"",IFERROR(WORKDAY(IK3,1,Feriados_BO_2026),WORKDAY(FechaInicioProyecto,233,Feriados_BO_2026))) | IM3: =IF(235>HorizonteDias,"",IFERROR(WORKDAY(IL3,1,Feriados_BO_2026),WORKDAY(FechaInicioProyecto,234,Feriados_BO_2026))) | IN3: =IF(236>HorizonteDias,"",IFERROR(WORKDAY(IM3,1,Feriados_BO_2026),WORKDAY(FechaInicioProyecto,235,Feriados_BO_2026))) | IO3: =IF(237>HorizonteDias,"",IFERROR(WORKDAY(IN3,1,Feriados_BO_2026),WORKDAY(FechaInicioProyecto,236,Feriados_BO_2026))) | IP3: =IF(238>HorizonteDias,"",IFERROR(WORKDAY(IO3,1,Feriados_BO_2026),WORKDAY(FechaInicioProyecto,237,Feriados_BO_2026))) | IQ3: =IF(239>HorizonteDias,"",IFERROR(WORKDAY(IP3,1,Feriados_BO_2026),WORKDAY(FechaInicioProyecto,238,Feriados_BO_2026))) | IR3: =IF(240>HorizonteDias,"",IFERROR(WORKDAY(IQ3,1,Feriados_BO_2026),WORKDAY(FechaInicioProyecto,239,Feriados_BO_2026))) | IS3: =IF(241>HorizonteDias,"",IFERROR(WORKDAY(IR3,1,Feriados_BO_2026),WORKDAY(FechaInicioProyecto,240,Feriados_BO_2026))) | IT3: =IF(242>HorizonteDias,"",IFERROR(WORKDAY(IS3,1,Feriados_BO_2026),WORKDAY(FechaInicioProyecto,241,Feriados_BO_2026))) | IU3: =IF(243>HorizonteDias,"",IFERROR(WORKDAY(IT3,1,Feriados_BO_2026),WORKDAY(FechaInicioProyecto,242,Feriados_BO_2026))) | IV3: =IF(244>HorizonteDias,"",IFERROR(WORKDAY(IU3,1,Feriados_BO_2026),WORKDAY(FechaInicioProyecto,243,Feriados_BO_2026))) | IW3: =IF(245>HorizonteDias,"",IFERROR(WORKDAY(IV3,1,Feriados_BO_2026),WORKDAY(FechaInicioProyecto,244,Feriados_BO_2026))) | IX3: =IF(246>HorizonteDias,"",IFERROR(WORKDAY(IW3,1,Feriados_BO_2026),WORKDAY(FechaInicioProyecto,245,Feriados_BO_2026))) | IY3: =IF(247>HorizonteDias,"",IFERROR(WORKDAY(IX3,1,Feriados_BO_2026),WORKDAY(FechaInicioProyecto,246,Feriados_BO_2026))) | IZ3: =IF(248>HorizonteDias,"",IFERROR(WORKDAY(IY3,1,Feriados_BO_2026),WORKDAY(FechaInicioProyecto,247,Feriados_BO_2026))) | JA3: =IF(249>HorizonteDias,"",IFERROR(WORKDAY(IZ3,1,Feriados_BO_2026),WORKDAY(FechaInicioProyecto,248,Feriados_BO_2026))) | JB3: =IF(250>HorizonteDias,"",IFERROR(WORKDAY(JA3,1,Feriados_BO_2026),WORKDAY(FechaInicioProyecto,249,Feriados_BO_2026))) | JC3: =IF(251>HorizonteDias,"",IFERROR(WORKDAY(JB3,1,Feriados_BO_2026),WORKDAY(FechaInicioProyecto,250,Feriados_BO_2026))) | JD3: =IF(252>HorizonteDias,"",IFERROR(WORKDAY(JC3,1,Feriados_BO_2026),WORKDAY(FechaInicioProyecto,251,Feriados_BO_2026))) | JE3: =IF(253>HorizonteDias,"",IFERROR(WORKDAY(JD3,1,Feriados_BO_2026),WORKDAY(FechaInicioProyecto,252,Feriados_BO_2026))) | JF3: =IF(254>HorizonteDias,"",IFERROR(WORKDAY(JE3,1,Feriados_BO_2026),WORKDAY(FechaInicioProyecto,253,Feriados_BO_2026))) | JG3: =IF(255>HorizonteDias,"",IFERROR(WORKDAY(JF3,1,Feriados_BO_2026),WORKDAY(FechaInicioProyecto,254,Feriados_BO_2026))) | JH3: =IF(256>HorizonteDias,"",IFERROR(WORKDAY(JG3,1,Feriados_BO_2026),WORKDAY(FechaInicioProyecto,255,Feriados_BO_2026))) | JI3: =IF(257>HorizonteDias,"",IFERROR(WORKDAY(JH3,1,Feriados_BO_2026),WORKDAY(FechaInicioProyecto,256,Feriados_BO_2026))) | JJ3: =IF(258>HorizonteDias,"",IFERROR(WORKDAY(JI3,1,Feriados_BO_2026),WORKDAY(FechaInicioProyecto,257,Feriados_BO_2026))) | JK3: =IF(259>HorizonteDias,"",IFERROR(WORKDAY(JJ3,1,Feriados_BO_2026),WORKDAY(FechaInicioProyecto,258,Feriados_BO_2026))) | JL3: =IF(260>HorizonteDias,"",IFERROR(WORKDAY(JK3,1,Feriados_BO_2026),WORKDAY(FechaInicioProyecto,259,Feriados_BO_2026)))
A4: 1. Planificación
B5: Definición de alcance | C5: PM | D5: =FechaInicioProyecto -> 46113 | E5: 2 | F5: =WORKDAY(D5,E5-1,Feriados_BO_2026) -> 46114 | G5: 46113 | H5: 46113 | I5: =IF($H5<>"",SIGN($H5-$F5)*(NETWORKDAYS(MIN($F5,$H5),MAX($F5,$H5),Feriados_BO_2026)-1),IF($G5<>"",IF(TODAY()>$F5,NETWORKDAYS($F5,TODAY(),Feriados_BO_2026)-1,0),IF(TODAY()>$D5,NETWORKDAYS($D5,TODAY(),Feriados_BO_2026)-1,0))) -> -1 | J5: 0.021 | K5: =SUM(J$5:J5) -> 0.021 | L5: Completado
B6: Viabilidad y recursos | C6: PM / Sponsor | D6: =WORKDAY(F5,1,Feriados_BO_2026) -> 46118 | E6: 1 | F6: =WORKDAY(D6,E6-1,Feriados_BO_2026) -> 46118 | G6: 46114 | H6: 46114 | I6: =IF($H6<>"",SIGN($H6-$F6)*(NETWORKDAYS(MIN($F6,$H6),MAX($F6,$H6),Feriados_BO_2026)-1),IF($G6<>"",IF(TODAY()>$F6,NETWORKDAYS($F6,TODAY(),Feriados_BO_2026)-1,0),IF(TODAY()>$D6,NETWORKDAYS($D6,TODAY(),Feriados_BO_2026)-1,0))) -> -1 | J6: 0.021 | K6: =SUM(J$5:J6) -> 0.042 | L6: Completado
B7: Cronograma inicial | C7: PM | D7: =WORKDAY(F6,1,Feriados_BO_2026) -> 46119 | E7: 1 | F7: =WORKDAY(D7,E7-1,Feriados_BO_2026) -> 46119 | G7: 46118 | H7: 46118 | I7: =IF($H7<>"",SIGN($H7-$F7)*(NETWORKDAYS(MIN($F7,$H7),MAX($F7,$H7),Feriados_BO_2026)-1),IF($G7<>"",IF(TODAY()>$F7,NETWORKDAYS($F7,TODAY(),Feriados_BO_2026)-1,0),IF(TODAY()>$D7,NETWORKDAYS($D7,TODAY(),Feriados_BO_2026)-1,0))) -> -1 | J7: 0.01 | K7: =SUM(J$5:J7) -> 0.052 | L7: Completado
A8: 2. Requisitos
B9: Levantamiento con cliente | C9: Analista | D9: =WORKDAY(F7,1,Feriados_BO_2026) -> 46120 | E9: 8 | F9: =WORKDAY(D9,E9-1,Feriados_BO_2026) -> 46129 | G9: 46122 | H9: 46127 | I9: =IF($H9<>"",SIGN($H9-$F9)*(NETWORKDAYS(MIN($F9,$H9),MAX($F9,$H9),Feriados_BO_2026)-1),IF($G9<>"",IF(TODAY()>$F9,NETWORKDAYS($F9,TODAY(),Feriados_BO_2026)-1,0),IF(TODAY()>$D9,NETWORKDAYS($D9,TODAY(),Feriados_BO_2026)-1,0))) -> -2 | J9: 0.042 | K9: =SUM(J$5:J9) -> 0.094 | L9: Completado
B10: Documentación de requisitos | C10: Analista | D10: =WORKDAY(F9,1,Feriados_BO_2026) -> 46132 | E10: 11 | F10: =WORKDAY(D10,E10-1,Feriados_BO_2026) -> 46147 | G10: 46132 | H10: 46146 | I10: =IF($H10<>"",SIGN($H10-$F10)*(NETWORKDAYS(MIN($F10,$H10),MAX($F10,$H10),Feriados_BO_2026)-1),IF($G10<>"",IF(TODAY()>$F10,NETWORKDAYS($F10,TODAY(),Feriados_BO_2026)-1,0),IF(TODAY()>$D10,NETWORKDAYS($D10,TODAY(),Feriados_BO_2026)-1,0))) -> -1 | J10: 0.031 | K10: =SUM(J$5:J10) -> 0.125 | L10: Completado
B11: Validación y aprobación | C11: PM / Cliente | D11: =WORKDAY(F10,1,Feriados_BO_2026) -> 46148 | E11: 1 | F11: =WORKDAY(D11,E11-1,Feriados_BO_2026) -> 46148 | G11: 46148 | H11: 46148 | I11: =IF($H11<>"",SIGN($H11-$F11)*(NETWORKDAYS(MIN($F11,$H11),MAX($F11,$H11),Feriados_BO_2026)-1),IF($G11<>"",IF(TODAY()>$F11,NETWORKDAYS($F11,TODAY(),Feriados_BO_2026)-1,0),IF(TODAY()>$D11,NETWORKDAYS($D11,TODAY(),Feriados_BO_2026)-1,0))) -> 0 | J11: 0.031 | K11: =SUM(J$5:J11) -> 0.156 | L11: Completado
A12: 3. Diseño
B13: Arquitectura del sistema | C13: Arquitecto | D13: =WORKDAY(F11,1,Feriados_BO_2026) -> 46149 | E13: 3 | F13: =WORKDAY(D13,E13-1,Feriados_BO_2026) -> 46153 | G13: 46154 | H13: 46155 | I13: =IF($H13<>"",SIGN($H13-$F13)*(NETWORKDAYS(MIN($F13,$H13),MAX($F13,$H13),Feriados_BO_2026)-1),IF($G13<>"",IF(TODAY()>$F13,NETWORKDAYS($F13,TODAY(),Feriados_BO_2026)-1,0),IF(TODAY()>$D13,NETWORKDAYS($D13,TODAY(),Feriados_BO_2026)-1,0))) -> 2 | J13: 0.042 | K13: =SUM(J$5:J13) -> 0.198 | L13: Completado
B14: Diseño de base de datos | C14: DBA | D14: =WORKDAY(F13,1,Feriados_BO_2026) -> 46154 | E14: 2 | F14: =WORKDAY(D14,E14-1,Feriados_BO_2026) -> 46155 | G14: 46155 | H14: 46156 | I14: =IF($H14<>"",SIGN($H14-$F14)*(NETWORKDAYS(MIN($F14,$H14),MAX($F14,$H14),Feriados_BO_2026)-1),IF($G14<>"",IF(TODAY()>$F14,NETWORKDAYS($F14,TODAY(),Feriados_BO_2026)-1,0),IF(TODAY()>$D14,NETWORKDAYS($D14,TODAY(),Feriados_BO_2026)-1,0))) -> 1 | J14: 0.031 | K14: =SUM(J$5:J14) -> 0.229 | L14: Completado
B15: Diseño UX/UI | C15: Diseñador | D15: =WORKDAY(F14,1,Feriados_BO_2026) -> 46156 | E15: 4 | F15: =WORKDAY(D15,E15-1,Feriados_BO_2026) -> 46161 | G15: 46155 | H15: 46156 | I15: =IF($H15<>"",SIGN($H15-$F15)*(NETWORKDAYS(MIN($F15,$H15),MAX($F15,$H15),Feriados_BO_2026)-1),IF($G15<>"",IF(TODAY()>$F15,NETWORKDAYS($F15,TODAY(),Feriados_BO_2026)-1,0),IF(TODAY()>$D15,NETWORKDAYS($D15,TODAY(),Feriados_BO_2026)-1,0))) -> -3 | J15: 0.042 | K15: =SUM(J$5:J15) -> 0.271 | L15: Completado
B16: Revisión y aprobación | C16: PM / Tech Lead | D16: =WORKDAY(F15,1,Feriados_BO_2026) -> 46162 | E16: 1 | F16: =WORKDAY(D16,E16-1,Feriados_BO_2026) -> 46162 | I16: =IF($H16<>"",SIGN($H16-$F16)*(NETWORKDAYS(MIN($F16,$H16),MAX($F16,$H16),Feriados_BO_2026)-1),IF($G16<>"",IF(TODAY()>$F16,NETWORKDAYS($F16,TODAY(),Feriados_BO_2026)-1,0),IF(TODAY()>$D16,NETWORKDAYS($D16,TODAY(),Feriados_BO_2026)-1,0))) -> 17 | J16: 0.021 | K16: =SUM(J$5:J16) -> 0.292 | L16: En curso
A17: 4. Desarrollo
B18: Configuración de entorno | C18: DevOps | D18: =WORKDAY(F16,1,Feriados_BO_2026) -> 46163 | E18: 2 | F18: =WORKDAY(D18,E18-1,Feriados_BO_2026) -> 46164 | G18: 46153 | H18: 46156 | I18: =IF($H18<>"",SIGN($H18-$F18)*(NETWORKDAYS(MIN($F18,$H18),MAX($F18,$H18),Feriados_BO_2026)-1),IF($G18<>"",IF(TODAY()>$F18,NETWORKDAYS($F18,TODAY(),Feriados_BO_2026)-1,0),IF(TODAY()>$D18,NETWORKDAYS($D18,TODAY(),Feriados_BO_2026)-1,0))) -> -6 | J18: 0.021 | K18: =SUM(J$5:J18) -> 0.313 | L18: Completado
B19: Módulo de autenticación | C19: Dev Backend | D19: =WORKDAY(F18,1,Feriados_BO_2026) -> 46167 | E19: 1 | F19: =WORKDAY(D19,E19-1,Feriados_BO_2026) -> 46167 | G19: 46154 | I19: =IF($H19<>"",SIGN($H19-$F19)*(NETWORKDAYS(MIN($F19,$H19),MAX($F19,$H19),Feriados_BO_2026)-1),IF($G19<>"",IF(TODAY()>$F19,NETWORKDAYS($F19,TODAY(),Feriados_BO_2026)-1,0),IF(TODAY()>$D19,NETWORKDAYS($D19,TODAY(),Feriados_BO_2026)-1,0))) -> 14 | J19: 0.052 | K19: =SUM(J$5:J19) -> 0.365 | L19: Pendiente
B20: Módulos funcionales core | C20: Equipo Dev | D20: =WORKDAY(F19,1,Feriados_BO_2026) -> 46168 | E20: 14 | F20: =WORKDAY(D20,E20-1,Feriados_BO_2026) -> 46188 | G20: 46132 | I20: =IF($H20<>"",SIGN($H20-$F20)*(NETWORKDAYS(MIN($F20,$H20),MAX($F20,$H20),Feriados_BO_2026)-1),IF($G20<>"",IF(TODAY()>$F20,NETWORKDAYS($F20,TODAY(),Feriados_BO_2026)-1,0),IF(TODAY()>$D20,NETWORKDAYS($D20,TODAY(),Feriados_BO_2026)-1,0))) -> 0 | J20: =Ponderaciones!E15 -> 0.1875 | K20: =SUM(J$5:J20) -> 0.5525 | L20: Pendiente
B21: Integraciones / APIs | C21: Dev Backend | D21: =WORKDAY(F20,1,Feriados_BO_2026) -> 46189 | E21: 11 | F21: =WORKDAY(D21,E21-1,Feriados_BO_2026) -> 46203 | G21: 46113 | I21: =IF($H21<>"",SIGN($H21-$F21)*(NETWORKDAYS(MIN($F21,$H21),MAX($F21,$H21),Feriados_BO_2026)-1),IF($G21<>"",IF(TODAY()>$F21,NETWORKDAYS($F21,TODAY(),Feriados_BO_2026)-1,0),IF(TODAY()>$D21,NETWORKDAYS($D21,TODAY(),Feriados_BO_2026)-1,0))) -> 0 | J21: 0.083 | K21: =SUM(J$5:J21) -> 0.6355 | L21: Pendiente
B22: Frontend y UI | C22: Dev Frontend | D22: =WORKDAY(F21,1,Feriados_BO_2026) -> 46204 | E22: 9 | F22: =WORKDAY(D22,E22-1,Feriados_BO_2026) -> 46216 | G22: 46125 | I22: =IF($H22<>"",SIGN($H22-$F22)*(NETWORKDAYS(MIN($F22,$H22),MAX($F22,$H22),Feriados_BO_2026)-1),IF($G22<>"",IF(TODAY()>$F22,NETWORKDAYS($F22,TODAY(),Feriados_BO_2026)-1,0),IF(TODAY()>$D22,NETWORKDAYS($D22,TODAY(),Feriados_BO_2026)-1,0))) -> 0 | J22: 0.083 | K22: =SUM(J$5:J22) -> 0.7185 | L22: Pendiente
A23: 5. Pruebas
B24: Pruebas unitarias | C24: Dev / QA | D24: =WORKDAY(F22,1,Feriados_BO_2026) -> 46217 | E24: 1 | F24: =WORKDAY(D24,E24-1,Feriados_BO_2026) -> 46217 | I24: =IF($H24<>"",SIGN($H24-$F24)*(NETWORKDAYS(MIN($F24,$H24),MAX($F24,$H24),Feriados_BO_2026)-1),IF($G24<>"",IF(TODAY()>$F24,NETWORKDAYS($F24,TODAY(),Feriados_BO_2026)-1,0),IF(TODAY()>$D24,NETWORKDAYS($D24,TODAY(),Feriados_BO_2026)-1,0))) -> 0 | J24: 0.042 | K24: =SUM(J$5:J24) -> 0.7605 | L24: Pendiente
B25: Pruebas de integración | C25: QA | D25: =WORKDAY(F24,1,Feriados_BO_2026) -> 46218 | E25: 2 | F25: =WORKDAY(D25,E25-1,Feriados_BO_2026) -> 46219 | I25: =IF($H25<>"",SIGN($H25-$F25)*(NETWORKDAYS(MIN($F25,$H25),MAX($F25,$H25),Feriados_BO_2026)-1),IF($G25<>"",IF(TODAY()>$F25,NETWORKDAYS($F25,TODAY(),Feriados_BO_2026)-1,0),IF(TODAY()>$D25,NETWORKDAYS($D25,TODAY(),Feriados_BO_2026)-1,0))) -> 0 | J25: 0.042 | K25: =SUM(J$5:J25) -> 0.8025 | L25: Pendiente
B26: Pruebas de usuario (UAT) | C26: QA / Cliente | D26: =WORKDAY(F25,1,Feriados_BO_2026) -> 46220 | E26: 2 | F26: =WORKDAY(D26,E26-1,Feriados_BO_2026) -> 46223 | I26: =IF($H26<>"",SIGN($H26-$F26)*(NETWORKDAYS(MIN($F26,$H26),MAX($F26,$H26),Feriados_BO_2026)-1),IF($G26<>"",IF(TODAY()>$F26,NETWORKDAYS($F26,TODAY(),Feriados_BO_2026)-1,0),IF(TODAY()>$D26,NETWORKDAYS($D26,TODAY(),Feriados_BO_2026)-1,0))) -> 0 | J26: 0.042 | K26: =SUM(J$5:J26) -> 0.8445 | L26: Pendiente
B27: Pruebas de ciberseguridad | C27: QA / DevOps | D27: =WORKDAY(F26,1,Feriados_BO_2026) -> 46224 | E27: 2 | F27: =WORKDAY(D27,E27-1,Feriados_BO_2026) -> 46225 | I27: =IF($H27<>"",SIGN($H27-$F27)*(NETWORKDAYS(MIN($F27,$H27),MAX($F27,$H27),Feriados_BO_2026)-1),IF($G27<>"",IF(TODAY()>$F27,NETWORKDAYS($F27,TODAY(),Feriados_BO_2026)-1,0),IF(TODAY()>$D27,NETWORKDAYS($D27,TODAY(),Feriados_BO_2026)-1,0))) -> 0 | J27: 0.052 | K27: =SUM(J$5:J27) -> 0.8965 | L27: Pendiente
B28: Corrección de bugs | C28: Dev | D28: =WORKDAY(F27,1,Feriados_BO_2026) -> 46226 | E28: 3 | F28: =WORKDAY(D28,E28-1,Feriados_BO_2026) -> 46230 | I28: =IF($H28<>"",SIGN($H28-$F28)*(NETWORKDAYS(MIN($F28,$H28),MAX($F28,$H28),Feriados_BO_2026)-1),IF($G28<>"",IF(TODAY()>$F28,NETWORKDAYS($F28,TODAY(),Feriados_BO_2026)-1,0),IF(TODAY()>$D28,NETWORKDAYS($D28,TODAY(),Feriados_BO_2026)-1,0))) -> 0 | J28: 0.031 | K28: =SUM(J$5:J28) -> 0.9275 | L28: Pendiente
A29: 6. Despliegue
B30: Preparación de entorno prod. | C30: DevOps | D30: =WORKDAY(F28,1,Feriados_BO_2026) -> 46231 | E30: 1 | F30: =WORKDAY(D30,E30-1,Feriados_BO_2026) -> 46231 | I30: =IF($H30<>"",SIGN($H30-$F30)*(NETWORKDAYS(MIN($F30,$H30),MAX($F30,$H30),Feriados_BO_2026)-1),IF($G30<>"",IF(TODAY()>$F30,NETWORKDAYS($F30,TODAY(),Feriados_BO_2026)-1,0),IF(TODAY()>$D30,NETWORKDAYS($D30,TODAY(),Feriados_BO_2026)-1,0))) -> 0 | J30: 0.021 | K30: =SUM(J$5:J30) -> 0.9485 | L30: Pendiente
B31: Pase a producción | C31: DevOps / PM | D31: =WORKDAY(F30,1,Feriados_BO_2026) -> 46232 | E31: 1 | F31: =WORKDAY(D31,E31-1,Feriados_BO_2026) -> 46232 | I31: =IF($H31<>"",SIGN($H31-$F31)*(NETWORKDAYS(MIN($F31,$H31),MAX($F31,$H31),Feriados_BO_2026)-1),IF($G31<>"",IF(TODAY()>$F31,NETWORKDAYS($F31,TODAY(),Feriados_BO_2026)-1,0),IF(TODAY()>$D31,NETWORKDAYS($D31,TODAY(),Feriados_BO_2026)-1,0))) -> 0 | J31: 0.031 | K31: =SUM(J$5:J31) -> 0.9795 | L31: Pendiente
B32: Capacitación a usuarios | C32: Analista | D32: =WORKDAY(F31,1,Feriados_BO_2026) -> 46233 | E32: 1 | F32: =WORKDAY(D32,E32-1,Feriados_BO_2026) -> 46233 | I32: =IF($H32<>"",SIGN($H32-$F32)*(NETWORKDAYS(MIN($F32,$H32),MAX($F32,$H32),Feriados_BO_2026)-1),IF($G32<>"",IF(TODAY()>$F32,NETWORKDAYS($F32,TODAY(),Feriados_BO_2026)-1,0),IF(TODAY()>$D32,NETWORKDAYS($D32,TODAY(),Feriados_BO_2026)-1,0))) -> 0 | J32: 0.021 | K32: =SUM(J$5:J32) -> 1.0005 | L32: Pendiente

Sheet Detalle de entregable
B1: REUNIÓN | C1: FRONTEND (Valor Visible / UX) | D1: BACKEND (Lógica, API y BD) | E1: HISTORIAS DE USUARIO | F1: PESO
B2: 🟢 R1: Seguridad + Base del Sistema + Parametrización | C2: Login real funcional. | D2: Autenticación (JWT/Sanctum) y gestión de roles/permisos. | E2: US-1.01, US-1.02, US-1.03, US-1.04, US-1.05, US-1.06, US-1.07, US-9.02, US-9.03, US-9.04, US-9.05 | F2: 6.5 / 10
C3: Vistas de perfil y configuración de delegados, vacaciones y reasignación. | D3: CRUD de usuarios y estados temporales (vacaciones, delegados).
C4: Parametrización interactiva (Diccionarios, SLAs, Matrices, Plantillas). | D4: Endpoints para catálogos y diccionarios del sistema.
D5: Lógica de reasignación masiva por desvinculación.
B6: 🔵 R2: Creación de Documento (UX completa) | C6: Wizard de creación paso a paso funcionando (datos, Outlook, archivos, revisores). | D6: Endpoints del Wizard (guardado en borrador por pasos). | E6: US-2.00, US-2.01, US-2.02, US-2.03, US-2.04, US-2.05, US-2.06 | F6: 7.5 / 10
C7: Gestión y validación visual de subida de archivos. | D7: Sistema de Storage (almacenamiento de archivos y plantillas).
C8: Envío exitoso del borrador a ETO. | D8: Generador automático de correlativos.
D9: Creación del registro inicial en la base de datos del flujo.
B10: 🟣 R3: Control ETO + Workflow Base | C10: Bandejas reactivas (Mi Bandeja y Bandeja ETO) con filtros. | D10: Motor de Workflow y transición de estados (En revisión, devuelto, aprobado). | E10: US-4.01, US-4.03, US-4.05, US-4.06, US-3.01, US-3.03, US-3.04, US-3.05 | F10: 8.5 / 10
C11: Vistas dinámicas para aprobación, devolución y corrección. | D11: Queries optimizadas para listar tareas pendientes por usuario/rol.
C12: Modal de modificación de flujo (rutas). | D12: Lógica de asignación y enrutamiento a siguientes revisores.
B13: 🔴 R4: Office 365 + IA Similitud + SLA | C13: Iframe/Integración visual para edición en línea (Office 365). | D13: Integración con API de Microsoft Graph (Webhooks, Lock/Unlock de archivos). | E13: US-3.02, US-3.06, US-4.02 | F13: 9.5 / 10
C14: Interfaz de resultados comparativos (IA Similitud). | D14: Conexión con LLM/Base Vectorial para análisis de similitud de textos.
C15: Alertas visuales y contadores de tiempo de SLA. | D15: Cronjobs / Queues nocturnos para cálculo automático y timeout de SLAs.
B16: 🟠 R5: PDF Oficial + Lista Maestra | C16: Componente Visor PDF global renderizando documentos. | D16: Motor de generación PDF (marcas de agua, carimbos, unión de carátula con doc). | E16: US-5.01, US-5.02, US-5.03, US-5.04, US-5.05, US-5.06, US-5.07 | F16: 9.0 / 10
C17: Interfaz de Lista Maestra real y Lista ETO. | D17: Endpoints complejos con filtros avanzados para Lista Maestra.
C18: Vistas de documentos obsoletos y próximos a vencer. | D18: Jobs programados para actualización de estados (Vencido / Obsoleto).
B19: 🟡 R6: Capacitación + Copias + BI + IA | C19: Formularios de exámenes y registro de capacitación. | D19: Lógica de calificación de evaluaciones. | E19: ÉPICAS 6, 7, 8 y 9 completas | F19: 7.5 / 10
C20: Monitor de copias controladas físicas. | D20: Trazabilidad y generador de marcas de agua para copias impresas.
C21: Dashboards, gráficos interactivos y componente de Chatbot IA. | D21: Consultas de agregación (Aggregate SQL) para Reportes BI.
D22: IA RAG Backend (Inyección de contexto BD hacia el modelo de lenguaje).

Sheet Dashboard
A1: Dashboard de Avance
A2: Fecha inicio | B2: =FechaInicioProyecto -> 46113 | C2: Días hábiles | D2: =HorizonteDias -> 84 | E2: Fecha fin | F2: =Configuración!B7 -> 46233
A4: Resumen por fase
A5: Fase | B5: Actividades | C5: Completadas | D5: Peso fase | E5: % Completado fase | G5: AVANCE REAL | H5: TAREAS RETRASADAS | I5: DESVÍO PROMEDIO
A6: 1. Planificación | B6: =COUNTA(Gantt!B5:B7) -> 3 | C6: =COUNTIF(Gantt!L5:L7,"Completado") -> 3 | D6: =SUM(Gantt!J5:J7) -> 0.052 | E6: {=SUMPRODUCT((Gantt!L5:L7="Completado")*Gantt!J5:J7)/D6} -> 1
A7: 2. Requisitos | B7: =COUNTA(Gantt!B9:B11) -> 3 | C7: =COUNTIF(Gantt!L9:L11,"Completado") -> 3 | D7: =SUM(Gantt!J9:J11) -> 0.104 | E7: {=SUMPRODUCT((Gantt!L9:L11="Completado")*Gantt!J9:J11)/D7} -> 1 | G7: =Gantt!K2 -> 0.292 | H7: =COUNTIF(Gantt!I5:I32,">0") -> 4 | I7: =AVERAGEIF(J19:J41,">0")&" días" -> 8,5 días
A8: 3. Diseño | B8: =COUNTA(Gantt!B13:B16) -> 4 | C8: =COUNTIF(Gantt!L13:L16,"Completado") -> 3 | D8: =SUM(Gantt!J13:J16) -> 0.136 | E8: {=SUMPRODUCT((Gantt!L13:L16="Completado")*Gantt!J13:J16)/D8} -> 0.84558824
A9: 4. Desarrollo | B9: =COUNTA(Gantt!B18:B22) -> 5 | C9: =COUNTIF(Gantt!L18:L22,"Completado") -> 1 | D9: =SUM(Gantt!J18:J22) -> 0.4265 | E9: {=SUMPRODUCT((Gantt!L18:L22="Completado")*Gantt!J18:J22)/D9} -> 0.049237984
A10: 5. Pruebas | B10: =COUNTA(Gantt!B24:B28) -> 5 | C10: =COUNTIF(Gantt!L24:L28,"Completado") -> 0 | D10: =SUM(Gantt!J24:J28) -> 0.209 | E10: {=SUMPRODUCT((Gantt!L24:L28="Completado")*Gantt!J24:J28)/D10} -> 0
A11: 6. Despliegue | B11: =COUNTA(Gantt!B30:B32) -> 3 | C11: =COUNTIF(Gantt!L30:L32,"Completado") -> 0 | D11: =SUM(Gantt!J30:J32) -> 0.073 | E11: {=SUMPRODUCT((Gantt!L30:L32="Completado")*Gantt!J30:J32)/D11} -> 0
A13: AVANCE TOTAL | C13: {=SUMPRODUCT((Gantt!L5:L32="Completado")*1)} -> 10 | D13: {=SUMPRODUCT((Gantt!L5:L32="Completado")*Gantt!J5:J32)} -> 0.292
A16: 📊 Análisis Gantt: Planificado vs Real (Todas las Actividades)
A18: Actividad | B18: Inicio Plan. | C18: Fin Plan. | D18: Inicio Real | E18: Fin Real | F18: Duración Plan. | G18: Duración Real | H18: Desv. Inicio | I18: Desv. Fin | J18: Desviación | K18: Estado
A19: =Gantt!B5 -> Definición de alcance | B19: =Gantt!D5 -> 46113 | C19: =Gantt!F5 -> 46114 | D19: =Gantt!G5 -> 46113 | E19: =Gantt!H5 -> 46113 | F19: =Gantt!E5 -> 2 | G19: =IF(E19>1,E19-D19+1,IF(D19>1,"🔄","")) -> 1 | H19: =IF(D19>1,D19-B19,"") -> 0 | I19: =IF(E19>1,E19-C19,"") -> -1 | J19: =Gantt!I5 -> -1 | K19: =Gantt!L5 -> Completado
A20: =Gantt!B6 -> Viabilidad y recursos | B20: =Gantt!D6 -> 46118 | C20: =Gantt!F6 -> 46118 | D20: =Gantt!G6 -> 46114 | E20: =Gantt!H6 -> 46114 | F20: =Gantt!E6 -> 1 | G20: =IF(E20>1,E20-D20+1,IF(D20>1,"🔄","")) -> 1 | H20: =IF(D20>1,D20-B20,"") -> -4 | I20: =IF(E20>1,E20-C20,"") -> -4 | J20: =Gantt!I6 -> -1 | K20: =Gantt!L6 -> Completado
A21: =Gantt!B7 -> Cronograma inicial | B21: =Gantt!D7 -> 46119 | C21: =Gantt!F7 -> 46119 | D21: =Gantt!G7 -> 46118 | E21: =Gantt!H7 -> 46118 | F21: =Gantt!E7 -> 1 | G21: =IF(E21>1,E21-D21+1,IF(D21>1,"🔄","")) -> 1 | H21: =IF(D21>1,D21-B21,"") -> -1 | I21: =IF(E21>1,E21-C21,"") -> -1 | J21: =Gantt!I7 -> -1 | K21: =Gantt!L7 -> Completado
A22: =Gantt!B9 -> Levantamiento con cliente | B22: =Gantt!D9 -> 46120 | C22: =Gantt!F9 -> 46129 | D22: =Gantt!G9 -> 46122 | E22: =Gantt!H9 -> 46127 | F22: =Gantt!E9 -> 8 | G22: =IF(E22>1,E22-D22+1,IF(D22>1,"🔄","")) -> 6 | H22: =IF(D22>1,D22-B22,"") -> 2 | I22: =IF(E22>1,E22-C22,"") -> -2 | J22: =Gantt!I9 -> -2 | K22: =Gantt!L9 -> Completado
A23: =Gantt!B10 -> Documentación de requisitos | B23: =Gantt!D10 -> 46132 | C23: =Gantt!F10 -> 46147 | D23: =Gantt!G10 -> 46132 | E23: =Gantt!H10 -> 46146 | F23: =Gantt!E10 -> 11 | G23: =IF(E23>1,E23-D23+1,IF(D23>1,"🔄","")) -> 15 | H23: =IF(D23>1,D23-B23,"") -> 0 | I23: =IF(E23>1,E23-C23,"") -> -1 | J23: =Gantt!I10 -> -1 | K23: =Gantt!L10 -> Completado
A24: =Gantt!B11 -> Validación y aprobación | B24: =Gantt!D11 -> 46148 | C24: =Gantt!F11 -> 46148 | D24: =Gantt!G11 -> 46148 | E24: =Gantt!H11 -> 46148 | F24: =Gantt!E11 -> 1 | G24: =IF(E24>1,E24-D24+1,IF(D24>1,"🔄","")) -> 1 | H24: =IF(D24>1,D24-B24,"") -> 0 | I24: =IF(E24>1,E24-C24,"") -> 0 | J24: =Gantt!I11 -> 0 | K24: =Gantt!L11 -> Completado
A25: =Gantt!B13 -> Arquitectura del sistema | B25: =Gantt!D13 -> 46149 | C25: =Gantt!F13 -> 46153 | D25: =Gantt!G13 -> 46154 | E25: =Gantt!H13 -> 46155 | F25: =Gantt!E13 -> 3 | G25: =IF(E25>1,E25-D25+1,IF(D25>1,"🔄","")) -> 2 | H25: =IF(D25>1,D25-B25,"") -> 5 | I25: =IF(E25>1,E25-C25,"") -> 2 | J25: =Gantt!I13 -> 2 | K25: =Gantt!L13 -> Completado
A26: =Gantt!B14 -> Diseño de base de datos | B26: =Gantt!D14 -> 46154 | C26: =Gantt!F14 -> 46155 | D26: =Gantt!G14 -> 46155 | E26: =Gantt!H14 -> 46156 | F26: =Gantt!E14 -> 2 | G26: =IF(E26>1,E26-D26+1,IF(D26>1,"🔄","")) -> 2 | H26: =IF(D26>1,D26-B26,"") -> 1 | I26: =IF(E26>1,E26-C26,"") -> 1 | J26: =Gantt!I14 -> 1 | K26: =Gantt!L14 -> Completado
A27: =Gantt!B15 -> Diseño UX/UI | B27: =Gantt!D15 -> 46156 | C27: =Gantt!F15 -> 46161 | D27: =Gantt!G15 -> 46155 | E27: =Gantt!H15 -> 46156 | F27: =Gantt!E15 -> 4 | G27: =IF(E27>1,E27-D27+1,IF(D27>1,"🔄","")) -> 2 | H27: =IF(D27>1,D27-B27,"") -> -1 | I27: =IF(E27>1,E27-C27,"") -> -5 | J27: =Gantt!I15 -> -3 | K27: =Gantt!L15 -> Completado
A28: =Gantt!B16 -> Revisión y aprobación | B28: =Gantt!D16 -> 46162 | C28: =Gantt!F16 -> 46162 | D28: =Gantt!G16 -> 0 | E28: =Gantt!H16 -> 0 | F28: =Gantt!E16 -> 1 | G28: =IF(E28>1,E28-D28+1,IF(D28>1,"🔄","")) | H28: =IF(D28>1,D28-B28,"") | I28: =IF(E28>1,E28-C28,"") | J28: =Gantt!I16 -> 17 | K28: =Gantt!L16 -> En curso
A29: =Gantt!B18 -> Configuración de entorno | B29: =Gantt!D18 -> 46163 | C29: =Gantt!F18 -> 46164 | D29: =Gantt!G18 -> 46153 | E29: =Gantt!H18 -> 46156 | F29: =Gantt!E18 -> 2 | G29: =IF(E29>1,E29-D29+1,IF(D29>1,"🔄","")) -> 4 | H29: =IF(D29>1,D29-B29,"") -> -10 | I29: =IF(E29>1,E29-C29,"") -> -8 | J29: =Gantt!I18 -> -6 | K29: =Gantt!L18 -> Completado
A30: =Gantt!B19 -> Módulo de autenticación | B30: =Gantt!D19 -> 46167 | C30: =Gantt!F19 -> 46167 | D30: =Gantt!G19 -> 46154 | E30: =Gantt!H19 -> 0 | F30: =Gantt!E19 -> 1 | G30: =IF(E30>1,E30-D30+1,IF(D30>1,"🔄","")) -> 🔄 | H30: =IF(D30>1,D30-B30,"") -> -13 | I30: =IF(E30>1,E30-C30,"") | J30: =Gantt!I19 -> 14 | K30: =Gantt!L19 -> Pendiente
A31: =Gantt!B20 -> Módulos funcionales core | B31: =Gantt!D20 -> 46168 | C31: =Gantt!F20 -> 46188 | D31: =Gantt!G20 -> 46132 | E31: =Gantt!H20 -> 0 | F31: =Gantt!E20 -> 14 | G31: =IF(E31>1,E31-D31+1,IF(D31>1,"🔄","")) -> 🔄 | H31: =IF(D31>1,D31-B31,"") -> -36 | I31: =IF(E31>1,E31-C31,"") | J31: =Gantt!I20 -> 0 | K31: =Gantt!L20 -> Pendiente
A32: =Gantt!B21 -> Integraciones / APIs | B32: =Gantt!D21 -> 46189 | C32: =Gantt!F21 -> 46203 | D32: =Gantt!G21 -> 46113 | E32: =Gantt!H21 -> 0 | F32: =Gantt!E21 -> 11 | G32: =IF(E32>1,E32-D32+1,IF(D32>1,"🔄","")) -> 🔄 | H32: =IF(D32>1,D32-B32,"") -> -76 | I32: =IF(E32>1,E32-C32,"") | J32: =Gantt!I21 -> 0 | K32: =Gantt!L21 -> Pendiente
A33: =Gantt!B22 -> Frontend y UI | B33: =Gantt!D22 -> 46204 | C33: =Gantt!F22 -> 46216 | D33: =Gantt!G22 -> 46125 | E33: =Gantt!H22 -> 0 | F33: =Gantt!E22 -> 9 | G33: =IF(E33>1,E33-D33+1,IF(D33>1,"🔄","")) -> 🔄 | H33: =IF(D33>1,D33-B33,"") -> -79 | I33: =IF(E33>1,E33-C33,"") | J33: =Gantt!I22 -> 0 | K33: =Gantt!L22 -> Pendiente
A34: =Gantt!B24 -> Pruebas unitarias | B34: =Gantt!D24 -> 46217 | C34: =Gantt!F24 -> 46217 | D34: =Gantt!G24 -> 0 | E34: =Gantt!H24 -> 0 | F34: =Gantt!E24 -> 1 | G34: =IF(E34>1,E34-D34+1,IF(D34>1,"🔄","")) | H34: =IF(D34>1,D34-B34,"") | I34: =IF(E34>1,E34-C34,"") | J34: =Gantt!I24 -> 0 | K34: =Gantt!L24 -> Pendiente
A35: =Gantt!B25 -> Pruebas de integración | B35: =Gantt!D25 -> 46218 | C35: =Gantt!F25 -> 46219 | D35: =Gantt!G25 -> 0 | E35: =Gantt!H25 -> 0 | F35: =Gantt!E25 -> 2 | G35: =IF(E35>1,E35-D35+1,IF(D35>1,"🔄","")) | H35: =IF(D35>1,D35-B35,"") | I35: =IF(E35>1,E35-C35,"") | J35: =Gantt!I25 -> 0 | K35: =Gantt!L25 -> Pendiente
A36: =Gantt!B26 -> Pruebas de usuario (UAT) | B36: =Gantt!D26 -> 46220 | C36: =Gantt!F26 -> 46223 | D36: =Gantt!G26 -> 0 | E36: =Gantt!H26 -> 0 | F36: =Gantt!E26 -> 2 | G36: =IF(E36>1,E36-D36+1,IF(D36>1,"🔄","")) | H36: =IF(D36>1,D36-B36,"") | I36: =IF(E36>1,E36-C36,"") | J36: =Gantt!I26 -> 0 | K36: =Gantt!L26 -> Pendiente
A37: =Gantt!B27 -> Pruebas de ciberseguridad | B37: =Gantt!D27 -> 46224 | C37: =Gantt!F27 -> 46225 | D37: =Gantt!G27 -> 0 | E37: =Gantt!H27 -> 0 | F37: =Gantt!E27 -> 2 | G37: =IF(E37>1,E37-D37+1,IF(D37>1,"🔄","")) | H37: =IF(D37>1,D37-B37,"") | I37: =IF(E37>1,E37-C37,"") | J37: =Gantt!I27 -> 0 | K37: =Gantt!L27 -> Pendiente
A38: =Gantt!B28 -> Corrección de bugs | B38: =Gantt!D28 -> 46226 | C38: =Gantt!F28 -> 46230 | D38: =Gantt!G28 -> 0 | E38: =Gantt!H28 -> 0 | F38: =Gantt!E28 -> 3 | G38: =IF(E38>1,E38-D38+1,IF(D38>1,"🔄","")) | H38: =IF(D38>1,D38-B38,"") | I38: =IF(E38>1,E38-C38,"") | J38: =Gantt!I28 -> 0 | K38: =Gantt!L28 -> Pendiente
A39: =Gantt!B30 -> Preparación de entorno prod. | B39: =Gantt!D30 -> 46231 | C39: =Gantt!F30 -> 46231 | D39: =Gantt!G30 -> 0 | E39: =Gantt!H30 -> 0 | F39: =Gantt!E30 -> 1 | G39: =IF(E39>1,E39-D39+1,IF(D39>1,"🔄","")) | H39: =IF(D39>1,D39-B39,"") | I39: =IF(E39>1,E39-C39,"") | J39: =Gantt!I30 -> 0 | K39: =Gantt!L30 -> Pendiente
A40: =Gantt!B31 -> Pase a producción | B40: =Gantt!D31 -> 46232 | C40: =Gantt!F31 -> 46232 | D40: =Gantt!G31 -> 0 | E40: =Gantt!H31 -> 0 | F40: =Gantt!E31 -> 1 | G40: =IF(E40>1,E40-D40+1,IF(D40>1,"🔄","")) | H40: =IF(D40>1,D40-B40,"") | I40: =IF(E40>1,E40-C40,"") | J40: =Gantt!I31 -> 0 | K40: =Gantt!L31 -> Pendiente
